"""
Script de prueba para verificar que los errores de lambda estÃ¡n corregidos
"""
print("ðŸ”§ Correcciones aplicadas:")
print()
print("âœ… Cliente (client.py):")
print("   - LÃ­nea ~421: Error de lambda con variable 'e' corregido")
print("   - Ahora usa: error_msg = f'Error...' y lambda msg=error_msg")
print()
print("âœ… Servidor (server.py):")
print("   - LÃ­nea ~320: Error en accept_connections corregido")
print("   - LÃ­nea ~412: Error en handle_client corregido") 
print("   - LÃ­nea ~423: Error en finally block corregido")
print()
print("ðŸŽ¯ Problema original:")
print("   NameError: cannot access free variable 'e' where it is not associated with a value")
print()
print("ðŸ”§ SoluciÃ³n aplicada:")
print("   En lugar de: lambda: self.add_log('Error', f'Error: {str(e)}')")
print("   Ahora usar: error_msg = f'Error: {str(e)}'")
print("             lambda msg=error_msg: self.add_log('Error', msg)")
print()
print("ðŸ’¡ Esto ocurre porque las lambdas no capturan automÃ¡ticamente las")
print("   variables del scope externo. Es necesario capturarlas explÃ­citamente")
print("   como parÃ¡metros con valores por defecto.")
print()
print("âœ… Sistema listo para usar sin errores de lambda!")
